Workbook
Name NativeTimeline_Date_Of_Joining: #N/A
Name Slicer_Department: #N/A
Name Slicer_Department1: #N/A
Name Slicer_Gender: #N/A
Name Slicer_Location: #N/A
Name Slicer_Payroll_Month: #N/A
Name Slicer_Status: #N/A
Name Slicer_Work_Location: #N/A

Sheet Employee Profile
A1: S. No. | B1: Employee Id | C1: First Name | D1: Last Name | E1: Gender | F1: Marital Status | G1: Age | H1: Date Of Birth | I1: Date Of Joining | J1: Date of Leaving | K1: Designation | L1: Department | M1: Reporting Manager | N1: Work Location | O1: Status | P1: Qualification | Q1: Shift Details | R1: PAN | S1: Email ID | T1: Phone | U1: Column1
A2: 1 | B2: ASG0001 | C2: Ajay | D2: Sharma | E2: Male | F2: Single | G2: =DATEDIF(H2, TODAY(), "Y") -> 48 | H2: 28678 | I2: 44593 | K2: HR Manager | L2: HR | M2: CEO | N2: Bangalore | O2: Active | P2: PG | Q2: Day | R2: BEJNS1637K | S2: ajay.sharma@asg.com | T2: 9100013338 | U2: =VLOOKUP($B2,Table2[[Employee Id]:[Annual CTC]],14,0) -> 1850000
A3: 2 | B3: ASG0002 | C3: Priya | D3: Kumar | E3: Female | F3: Married | G3: =DATEDIF(H3, TODAY(), "Y") -> 46 | H3: 29166 | I3: 44613 | K3: Analytics Manager | L3: Analytics | M3: CEO | N3: Chennai | O3: Active | P3: PG | Q3: Day | R3: EHMRV2048G | S3: priya.kumar@asg.com | T3: 9100053364 | U3: =VLOOKUP($B3,Table2[[Employee Id]:[Annual CTC]],14,0) -> 2500000 | V3: Total Employees | W3: =COUNTA(Table1[Employee Id]) -> 50
A4: 3 | B4: ASG0003 | C4: Aarav | D4: Pillai | E4: Male | F4: Single | G4: =DATEDIF(H4, TODAY(), "Y") -> 44 | H4: 29999 | I4: 44634 | K4: HR Manager | L4: HR | M4: CEO | N4: Bangalore | O4: Active | P4: PG | Q4: Day | R4: KNSWA2733T | S4: aarav.pillai@asg.com | T4: 9100120114 | U4: =VLOOKUP($B4,Table2[[Employee Id]:[Annual CTC]],14,0) -> 1750000
A5: 4 | B5: ASG0004 | C5: Pooja | D5: Reddy | E5: Female | F5: Single | G5: =DATEDIF(H5, TODAY(), "Y") -> 35 | H5: 33365 | I5: 44676 | J5: 45886 | K5: BI Developer | L5: Analytics | M5: ASG0002 | N5: Mumbai | O5: Relieved | P5: PG | Q5: Night | R5: LPTXB2870A | S5: pooja.reddy@asg.com | T5: 9100133470 | U5: =VLOOKUP($B5,Table2[[Employee Id]:[Annual CTC]],14,0) -> 1350000 | V5: Active Employees | W5: =COUNTIF(Table1[Status],"Active") -> 38
A6: 5 | B6: ASG0005 | C6: Tarun | D6: Shah | E6: Male | F6: Married | G6: =DATEDIF(H6, TODAY(), "Y") -> 34 | H6: 33723 | I6: 44697 | K6: Payroll Manager | L6: Payroll | M6: CEO | N6: Chennai | O6: Active | P6: PG | Q6: Day | R6: NRVZD3144Q | S6: tarun.shah@asg.com | T6: 9100160188 | U6: =VLOOKUP($B6,Table2[[Employee Id]:[Annual CTC]],14,0) -> 1700000
A7: 6 | B7: ASG0006 | C7: Varun | D7: Iyer | E7: Male | F7: Single | G7: =DATEDIF(H7, TODAY(), "Y") -> 33 | H7: 34064 | I7: 44704 | K7: Senior Payroll Analyst | L7: Payroll | M7: ASG0005 | N7: Mumbai | O7: Active | P7: PG | Q7: Mid | R7: QTXBF3418E | S7: varun.iyer@asg.com | T7: 9100186914 | U7: =VLOOKUP($B7,Table2[[Employee Id]:[Annual CTC]],14,0) -> 1000000 | V7: No. of Departments | W7: =COUNTA(_xlfn.UNIQUE(Table1[Department])) -> 5
A8: 7 | B8: ASG0007 | C8: Sachin | D8: Sinha | E8: Male | F8: Single | G8: =DATEDIF(H8, TODAY(), "Y") -> 32 | H8: 34296 | I8: 44802 | J8: 45951 | K8: Senior Payroll Analyst | L8: Payroll | M8: ASG0005 | N8: Chennai | O8: Relieved | P8: UG | Q8: Night | R8: WZDHM4240Y | S8: sachin.sinha@asg.com | T8: 9100253764 | U8: =VLOOKUP($B8,Table2[[Employee Id]:[Annual CTC]],14,0) -> 950000
A9: 8 | B9: ASG0008 | C9: Rajesh | D9: Mishra | E9: Male | F9: Single | G9: =DATEDIF(H9, TODAY(), "Y") -> 33 | H9: 34123 | I9: 44886 | K9: Sales Manager | L9: Sales | M9: CEO | N9: Kolkata | O9: Active | P9: PG | Q9: Day | R9: YBFKP4514N | S9: rajesh.mishra@asg.com | T9: 9100280518 | U9: =VLOOKUP($B9,Table2[[Employee Id]:[Annual CTC]],14,0) -> 2100000 | V9: No. of Locations | W9: =COUNTA(_xlfn.UNIQUE(Table1[Work Location])) -> 5
A10: 9 | B10: ASG0009 | C10: Arnav | D10: Pandey | E10: Male | F10: Married | G10: =DATEDIF(H10, TODAY(), "Y") -> 32 | H10: 34429 | I10: 44893 | K10: Regional Sales Lead | L10: Sales | M10: ASG0008 | N10: Hyderabad | O10: Active | P10: PG | Q10: Day | R10: DGLQU5199Z | S10: arnav.pandey@asg.com | T10: 9100347438 | U10: =VLOOKUP($B10,Table2[[Employee Id]:[Annual CTC]],14,0) -> 1800000
A11: 10 | B11: ASG0010 | C11: Tushar | D11: Arora | E11: Male | F11: Single | G11: =DATEDIF(H11, TODAY(), "Y") -> 32 | H11: 34309 | I11: 44907 | K11: Finance Manager | L11: Finance | M11: CEO | N11: Mumbai | O11: Active | P11: PG | Q11: Day | R11: GKPTX5610W | S11: tushar.arora@asg.com | T11: 9100387614 | U11: =VLOOKUP($B11,Table2[[Employee Id]:[Annual CTC]],14,0) -> 1750000
A12: 11 | B12: ASG0011 | C12: Nidhi | D12: Nayak | E12: Female | F12: Single | G12: =DATEDIF(H12, TODAY(), "Y") -> 31 | H12: 34753 | I12: 44935 | J12: 45979 | K12: Regional Sales Lead | L12: Sales | M12: ASG0008 | N12: Hyderabad | O12: Relieved | P12: PG | Q12: Day | R12: MQUYC6295H | S12: nidhi.nayak@asg.com | T12: 9100494838 | U12: =VLOOKUP($B12,Table2[[Employee Id]:[Annual CTC]],14,0) -> 1800000
A13: 12 | B13: ASG0012 | C13: Manish | D13: Hegde | E13: Male | F13: Single | G13: =DATEDIF(H13, TODAY(), "Y") -> 30 | H13: 35180 | I13: 44956 | K13: Senior Sales Executive | L13: Sales | M13: ASG0009 | N13: Chennai | O13: Active | P13: PG | Q13: Day | R13: NRVZD6432Q | S13: manish.hegde@asg.com | T13: 9100508250 | U13: =VLOOKUP($B13,Table2[[Employee Id]:[Annual CTC]],14,0) -> 1150000
A14: 13 | B14: ASG0013 | C14: Piyush | D14: Shetty | E14: Male | F14: Single | G14: =DATEDIF(H14, TODAY(), "Y") -> 31 | H14: 34869 | I14: 44963 | K14: Senior Data Analyst | L14: Analytics | M14: ASG0002 | N14: Bangalore | O14: Active | P14: PG | Q14: Day | R14: PSWAE6569X | S14: piyush.shetty@asg.com | T14: 9100521664 | U14: =VLOOKUP($B14,Table2[[Employee Id]:[Annual CTC]],14,0) -> 1550000
A15: 14 | B15: ASG0014 | C15: Shruti | D15: Gowda | E15: Female | F15: Single | G15: =DATEDIF(H15, TODAY(), "Y") -> 30 | H15: 35228 | I15: 45005 | J15: 45919 | K15: Payroll Analyst | L15: Payroll | M15: ASG0006 | N15: Kolkata | O15: Relieved | P15: UG | Q15: Mid | R15: QTXBF6706E | S15: shruti.gowda@asg.com | T15: 9100535080 | U15: =VLOOKUP($B15,Table2[[Employee Id]:[Annual CTC]],14,0) -> 650000
A16: 15 | B16: ASG0015 | C16: Sumit | D16: Garg | E16: Male | F16: Single | G16: =DATEDIF(H16, TODAY(), "Y") -> 29 | H16: 35553 | I16: 45033 | K16: Senior Data Analyst | L16: Analytics | M16: ASG0002 | N16: Hyderabad | O16: Active | P16: PG | Q16: Mid | R16: RUYCG6843M | S16: sumit.garg@asg.com | T16: 9100548498 | U16: =VLOOKUP($B16,Table2[[Employee Id]:[Annual CTC]],14,0) -> 1475000
A17: 16 | B17: ASG0016 | C17: Saurab | D17: Bansal | E17: Male | F17: Single | G17: =DATEDIF(H17, TODAY(), "Y") -> 28 | H17: 35855 | I17: 45040 | K17: Senior Data Analyst | L17: Analytics | M17: ASG0002 | N17: Bangalore | O17: Active | P17: PG | Q17: Night | R17: TWAEJ7117B | S17: saurab.bansal@asg.com | T17: 9100575340 | U17: =VLOOKUP($B17,Table2[[Employee Id]:[Annual CTC]],14,0) -> 1875000
A18: 17 | B18: ASG0017 | C18: Yuvraj | D18: Saxena | E18: Male | F18: Single | G18: =DATEDIF(H18, TODAY(), "Y") -> 29 | H18: 35631 | I18: 45048 | J18: 46055 | K18: Sr Accountant | L18: Finance | M18: ASG0010 | N18: Chennai | O18: Relieved | P18: PG | Q18: Mid | R18: WZDHM7528Y | S18: yuvraj.saxena@asg.com | T18: 9100615618 | U18: =VLOOKUP($B18,Table2[[Employee Id]:[Annual CTC]],14,0) -> 1150000
A19: 18 | B19: ASG0018 | C19: Pranav | D19: Tripathi | E19: Male | F19: Single | G19: =DATEDIF(H19, TODAY(), "Y") -> 28 | H19: 35818 | I19: 45075 | K19: Sr Accountant | L19: Finance | M19: ASG0010 | N19: Bangalore | O19: Active | P19: PG | Q19: Day | R19: XAEJN7665F | S19: pranav.tripathi@asg.com | T19: 9100629048 | U19: =VLOOKUP($B19,Table2[[Employee Id]:[Annual CTC]],14,0) -> 1125000
A20: 19 | B20: ASG0019 | C20: Simran | D20: Jain | E20: Female | F20: Single | G20: =DATEDIF(H20, TODAY(), "Y") -> 28 | H20: 35785 | I20: 45170 | K20: Senior Sales Executive | L20: Sales | M20: ASG0009 | N20: Mumbai | O20: Active | P20: UG | Q20: Mid | R20: YBFKP7802N | S20: simran.jain@asg.com | T20: 9100642480 | U20: =VLOOKUP($B20,Table2[[Employee Id]:[Annual CTC]],14,0) -> 1100000
A21: 20 | B21: ASG0020 | C21: Kartik | D21: Batra | E21: Male | F21: Single | G21: =DATEDIF(H21, TODAY(), "Y") -> 29 | H21: 35644 | I21: 45173 | K21: Sales Executive | L21: Sales | M21: ASG0012 | N21: Kolkata | O21: Active | P21: UG | Q21: Day | R21: CFKPT8350S | S21: kartik.batra@asg.com | T21: 9100736560 | U21: =VLOOKUP($B21,Table2[[Employee Id]:[Annual CTC]],14,0) -> 780000
A22: 21 | B22: ASG0021 | C22: Ritesh | D22: Luthra | E22: Male | F22: Single | G22: =DATEDIF(H22, TODAY(), "Y") -> 28 | H22: 35993 | I22: 45222 | J22: 45950 | K22: Payroll Analyst | L22: Payroll | M22: ASG0006 | N22: Hyderabad | O22: Relieved | P22: PG | Q22: Night | R22: EHMRV8624G | S22: ritesh.luthra@asg.com | T22: 9100750008 | U22: =VLOOKUP($B22,Table2[[Employee Id]:[Annual CTC]],14,0) -> 675000
A23: 22 | B23: ASG0022 | C23: Lokesh | D23: Ahuja | E23: Male | F23: Single | G23: =DATEDIF(H23, TODAY(), "Y") -> 27 | H23: 36255 | I23: 45236 | K23: Payroll Analyst | L23: Payroll | M23: ASG0006 | N23: Mumbai | O23: Active | P23: UG | Q23: Mid | R23: GKPTX8898W | S23: lokesh.ahuja@asg.com | T23: 9100776910 | U23: =VLOOKUP($B23,Table2[[Employee Id]:[Annual CTC]],14,0) -> 680000
A24: 23 | B24: ASG0023 | C24: Sonia | D24: Khanna | E24: Female | F24: Single | G24: =DATEDIF(H24, TODAY(), "Y") -> 27 | H24: 36069 | I24: 45320 | K24: HR Analyst | L24: HR | M24: ASG0001 | N24: Hyderabad | O24: Active | P24: PG | Q24: Mid | R24: HLQUY9035D | S24: sonia.khanna@asg.com | T24: 9100790364 | U24: =VLOOKUP($B24,Table2[[Employee Id]:[Annual CTC]],14,0) -> 1200000
A25: 24 | B25: ASG0024 | C25: Parth | D25: Madaan | E25: Male | F25: Married | G25: =DATEDIF(H25, TODAY(), "Y") -> 26 | H25: 36527 | I25: 45327 | J25: 46084 | K25: Accounts Executive | L25: Finance | M25: ASG0018 | N25: Kolkata | O25: Relieved | P25: PG | Q25: Day | R25: YBFKP2090N | S25: parth.madaan@asg.com | T25: 9100803820 | U25: =VLOOKUP($B25,Table2[[Employee Id]:[Annual CTC]],14,0) -> 780000
A26: 25 | B26: ASG0025 | C26: Akshay | D26: Mohan | E26: Male | F26: Single | G26: =DATEDIF(H26, TODAY(), "Y") -> 26 | H26: 36614 | I26: 45328 | K26: Accounts Executive | L26: Finance | M26: ASG0018 | N26: Chennai | O26: Active | P26: PG | Q26: Mid | R26: NRVZD9720Q | S26: akshay.mohan@asg.com | T26: 9100884598 | U26: =VLOOKUP($B26,Table2[[Employee Id]:[Annual CTC]],14,0) -> 725000
A27: 26 | B27: ASG0026 | C27: Sanjay | D27: Lal | E27: Male | F27: Single | G27: =DATEDIF(H27, TODAY(), "Y") -> 26 | H27: 36446 | I27: 45404 | J27: 46012 | K27: Sales Executive | L27: Sales | M27: ASG0019 | N27: Bangalore | O27: Relieved | P27: UG | Q27: Mid | R27: PSWAE9857X | S27: sanjay.lal@asg.com | T27: 9100898068 | U27: =VLOOKUP($B27,Table2[[Employee Id]:[Annual CTC]],14,0) -> 825000
A28: 27 | B28: ASG0027 | C28: Ashwin | D28: Gill | E28: Male | F28: Single | G28: =DATEDIF(H28, TODAY(), "Y") -> 28 | H28: 35935 | I28: 45418 | K28: HR Analyst | L28: HR | M28: ASG0003 | N28: Mumbai | O28: Active | P28: PG | Q28: Day | R28: QTXBF9994E | S28: ashwin.gill@asg.com | T28: 9100911540 | U28: =VLOOKUP($B28,Table2[[Employee Id]:[Annual CTC]],14,0) -> 1150000
A29: 28 | B29: ASG0028 | C29: Naveen | D29: Samant | E29: Male | F29: Single | G29: =DATEDIF(H29, TODAY(), "Y") -> 27 | H29: 36318 | I29: 45502 | K29: Sales Trainee | L29: Sales | M29: ASG0012 | N29: Hyderabad | O29: Active | P29: UG | Q29: Day | R29: RUYCG1131M | S29: naveen.samant@asg.com | T29: 9100925014 | U29: =VLOOKUP($B29,Table2[[Employee Id]:[Annual CTC]],14,0) -> 450000
A30: 29 | B30: ASG0029 | C30: Girish | D30: Mistry | E30: Male | F30: Single | G30: =DATEDIF(H30, TODAY(), "Y") -> 26 | H30: 36597 | I30: 45509 | K30: Payroll Analyst | L30: Payroll | M30: ASG0006 | N30: Kolkata | O30: Active | P30: UG | Q30: Night | R30: UXBFK1542J | S30: girish.mistry@asg.com | T30: 9100965448 | U30: =VLOOKUP($B30,Table2[[Employee Id]:[Annual CTC]],14,0) -> 650000
A31: 30 | B31: ASG0030 | C31: Kavya | D31: Shroff | E31: Female | F31: Single | G31: =DATEDIF(H31, TODAY(), "Y") -> 26 | H31: 36496 | I31: 45537 | J31: 46098 | K31: Senior Data Analyst | L31: Analytics | M31: ASG0002 | N31: Hyderabad | O31: Relieved | P31: PG | Q31: Day | R31: ZCGLQ2227V | S31: kavya.shroff@asg.com | T31: 9100992414 | U31: =VLOOKUP($B31,Table2[[Employee Id]:[Annual CTC]],14,0) -> 1435000
A32: 31 | B32: ASG0031 | C32: Harish | D32: Dalal | E32: Male | F32: Single | G32: =DATEDIF(H32, TODAY(), "Y") -> 26 | H32: 36663 | I32: 45579 | K32: Accounts Executive | L32: Finance | M32: ASG0018 | N32: Bangalore | O32: Active | P32: UG | Q32: Mid | R32: BEJNS2501K | S32: harish.dalal@asg.com | T32: 9101005900 | U32: =VLOOKUP($B32,Table2[[Employee Id]:[Annual CTC]],14,0) -> 700000
A33: 32 | B33: ASG0032 | C33: Ramesh | D33: Sibal | E33: Male | F33: Married | G33: =DATEDIF(H33, TODAY(), "Y") -> 26 | H33: 36754 | I33: 45607 | K33: HR Executive | L33: HR | M33: ASG0023 | N33: Chennai | O33: Active | P33: PG | Q33: Mid | R33: SVZDH4556U | S33: ramesh.sibal@asg.com | T33: 9101032878 | U33: =VLOOKUP($B33,Table2[[Employee Id]:[Annual CTC]],14,0) -> 750000
A34: 33 | B34: ASG0033 | C34: Nisha | D34: Madan | E34: Female | F34: Married | G34: =DATEDIF(H34, TODAY(), "Y") -> 25 | H34: 36935 | I34: 45614 | K34: Data Analyst | L34: Analytics | M34: ASG0013 | N34: Bangalore | O34: Active | P34: UG | Q34: Day | R34: TWAEJ4693B | S34: nisha.madan@asg.com | T34: 9101046370 | U34: =VLOOKUP($B34,Table2[[Employee Id]:[Annual CTC]],14,0) -> 1250000
A35: 34 | B35: ASG0034 | C35: Dinesh | D35: Kohli | E35: Male | F35: Single | G35: =DATEDIF(H35, TODAY(), "Y") -> 26 | H35: 36784 | I35: 45649 | J35: 46041 | K35: HR Executive | L35: HR | M35: ASG0027 | N35: Chennai | O35: Relieved | P35: UG | Q35: Day | R35: ADHMR2364C | S35: dinesh.kohli@asg.com | T35: 9101059864 | U35: =VLOOKUP($B35,Table2[[Employee Id]:[Annual CTC]],14,0) -> 625000
A36: 35 | B36: ASG0035 | C36: Sunil | D36: Jolly | E36: Male | F36: Single | G36: =DATEDIF(H36, TODAY(), "Y") -> 25 | H36: 36892 | I36: 45663 | K36: HR Executive | L36: HR | M36: ASG0027 | N36: Mumbai | O36: Active | P36: UG | Q36: Day | R36: CFKPT2638S | S36: sunil.jolly@asg.com | T36: 9101073360 | U36: =VLOOKUP($B36,Table2[[Employee Id]:[Annual CTC]],14,0) -> 600000
A37: 36 | B37: ASG0036 | C37: Bikram | D37: Monga | E37: Male | F37: Single | G37: =DATEDIF(H37, TODAY(), "Y") -> 26 | H37: 36678 | I37: 45782 | K37: Payroll Executive | L37: Payroll | M37: ASG0022 | N37: Chennai | O37: Active | P37: UG | Q37: Mid | R37: EHMRV2912G | S37: bikram.monga@asg.com | T37: 9101100358 | U37: =VLOOKUP($B37,Table2[[Employee Id]:[Annual CTC]],14,0) -> 475000
A38: 37 | B38: ASG0037 | C38: Pratik | D38: Nanda | E38: Male | F38: Single | G38: =DATEDIF(H38, TODAY(), "Y") -> 25 | H38: 36860 | I38: 45831 | J38: 46008 | K38: Accounts Trainee | L38: Finance | M38: ASG0018 | N38: Bangalore | O38: Relieved | P38: UG | Q38: Day | R38: FJNSW3049P | S38: pratik.nanda@asg.com | T38: 9101113860 | U38: =VLOOKUP($B38,Table2[[Employee Id]:[Annual CTC]],14,0) -> 450000
A39: 38 | B39: ASG0038 | C39: Rohini | D39: Suri | E39: Female | F39: Single | G39: =DATEDIF(H39, TODAY(), "Y") -> 25 | H39: 36926 | I39: 45852 | K39: Accounts Trainee | L39: Finance | M39: ASG0018 | N39: Mumbai | O39: Active | P39: UG | Q39: Mid | R39: GKPTX3186W | S39: rohini.suri@asg.com | T39: 9101127364 | U39: =VLOOKUP($B39,Table2[[Employee Id]:[Annual CTC]],14,0) -> 450000
A40: 39 | B40: ASG0039 | C40: Abhinav | D40: Khera | E40: Male | F40: Single | G40: =DATEDIF(H40, TODAY(), "Y") -> 25 | H40: 36937 | I40: 45901 | K40: BI Developer | L40: Analytics | M40: ASG0002 | N40: Kolkata | O40: Active | P40: UG | Q40: Night | R40: UXBFK4830J | S40: abhinav.khera@asg.com | T40: 9101140870 | U40: =VLOOKUP($B40,Table2[[Employee Id]:[Annual CTC]],14,0) -> 1275000
...

Sheet Pivot Tables - Workforce
A1: Count of Employee Id | B1: Column Labels | D1: Rs. #\.##,"L" | F1: Department | G1: Count of Employee Id | J1: Count of Employee Id | K1: Column Labels
A2: Department | B2: Active | C2: Relieved | F2: PG | G2: 27 | J2: Department | K2: Female | L2: Male
A3: Analytics | B3: 8 | C3: 2 | F3: UG | G3: 23 | J3: Analytics | K3: 5 | L3: 5
A4: Finance | B4: 7 | C4: 3 | J4: Finance | K4: 1 | L4: 9
A5: HR | B5: 9 | C5: 1 | J5: HR | K5: 3 | L5: 7
A6: Payroll | B6: 6 | C6: 4 | J6: Payroll | K6: 1 | L6: 9
A7: Sales | B7: 8 | C7: 2 | J7: Sales | K7: 2 | L7: 8
F23: Department | G23: Count of Employee Id
F24: Day | G24: 25 | J24: Count of Employee Id | K24: Column Labels
F25: Mid | G25: 17 | J25: Department | K25: Analytics | L25: Finance | M25: HR | N25: Payroll | O25: Sales
A26: Location | B26: Count of Employee Id | F26: Night | G26: 8 | J26: Bangalore | K26: 3 | L26: 3 | M26: 4 | O26: 1
A27: Bangalore | B27: 11 | J27: Chennai | K27: 2 | L27: 2 | M27: 3 | N27: 3 | O27: 2
A28: Chennai | B28: 12 | J28: Hyderabad | K28: 2 | L28: 1 | M28: 1 | N28: 2 | O28: 4
A29: Hyderabad | B29: 10 | J29: Kolkata | K29: 2 | L29: 1 | N29: 2 | O29: 2
A30: Mumbai | B30: 10 | J30: Mumbai | K30: 1 | L30: 3 | M30: 2 | N30: 3 | O30: 1
A31: Kolkata | B31: 7

Sheet Dashboard for Emp Workforce

Sheet Business Insights for Workforce

Sheet CTC Breakup
A1: S. No. | B1: Employee Id | C1: Date Of Joining | D1: Date of Leaving | E1: Status | F1: Designation | G1: Department | H1: Basic (50% of CTC) | I1: HRA (40% of Basic) | J1: Special Allowance (Adjusting Figure) | K1: Fuel Allowance (Fixed Rs 2000) | L1: Internet Allowance (Fixed Rs 1000) | M1: Employer PF (Basic * 12%) | N1: Monthly CTC | O1: Annual CTC
A2: 1 | B2: ASG0001 | C2: 44593 | E2: Active | F2: HR Manager | G2: HR | H2: =ROUND(N2/2,0) -> 77084 | I2: =ROUND(H2*40%,0) -> 30834 | J2: =N2-H2-I2-K2-L2-M2 -> 33999 | K2: 2000 | L2: 1000 | M2: =ROUND(H2*12%,0) -> 9250 | N2: =ROUND(O2/12,0) -> 154167 | O2: 1850000
A3: 2 | B3: ASG0002 | C3: 44613 | E3: Active | F3: Analytics Manager | G3: Analytics | H3: =ROUND(N3/2,0) -> 104167 | I3: =ROUND(H3*40%,0) -> 41667 | J3: =N3-H3-I3-K3-L3-M3 -> 49999 | M3: =ROUND(H3*12%,0) -> 12500 | N3: =ROUND(O3/12,0) -> 208333 | O3: 2500000
A4: 3 | B4: ASG0003 | C4: 44634 | E4: Active | F4: HR Manager | G4: HR | H4: =ROUND(N4/2,0) -> 72917 | I4: =ROUND(H4*40%,0) -> 29167 | J4: =N4-H4-I4-K4-L4-M4 -> 31999 | K4: 2000 | L4: 1000 | M4: =ROUND(H4*12%,0) -> 8750 | N4: =ROUND(O4/12,0) -> 145833 | O4: 1750000
A5: 4 | B5: ASG0004 | C5: 44676 | D5: 45886 | E5: Relieved | F5: BI Developer | G5: Analytics | H5: =ROUND(N5/2,0) -> 56250 | I5: =ROUND(H5*40%,0) -> 22500 | J5: =N5-H5-I5-K5-L5-M5 -> 24000 | K5: 2000 | L5: 1000 | M5: =ROUND(H5*12%,0) -> 6750 | N5: =ROUND(O5/12,0) -> 112500 | O5: 1350000
A6: 5 | B6: ASG0005 | C6: 44697 | E6: Active | F6: Payroll Manager | G6: Payroll | H6: =ROUND(N6/2,0) -> 70834 | I6: =ROUND(H6*40%,0) -> 28334 | J6: =N6-H6-I6-K6-L6-M6 -> 30999 | K6: 2000 | L6: 1000 | M6: =ROUND(H6*12%,0) -> 8500 | N6: =ROUND(O6/12,0) -> 141667 | O6: 1700000
A7: 6 | B7: ASG0006 | C7: 44704 | E7: Active | F7: Senior Payroll Analyst | G7: Payroll | H7: =ROUND(N7/2,0) -> 41667 | I7: =ROUND(H7*40%,0) -> 16667 | J7: =N7-H7-I7-K7-L7-M7 -> 16999 | K7: 2000 | L7: 1000 | M7: =ROUND(H7*12%,0) -> 5000 | N7: =ROUND(O7/12,0) -> 83333 | O7: 1000000
A8: 7 | B8: ASG0007 | C8: 44802 | D8: 45951 | E8: Relieved | F8: Senior Payroll Analyst | G8: Payroll | H8: =ROUND(N8/2,0) -> 39584 | I8: =ROUND(H8*40%,0) -> 15834 | J8: =N8-H8-I8-K8-L8-M8 -> 15999 | K8: 2000 | L8: 1000 | M8: =ROUND(H8*12%,0) -> 4750 | N8: =ROUND(O8/12,0) -> 79167 | O8: 950000
A9: 8 | B9: ASG0008 | C9: 44886 | E9: Active | F9: Sales Manager | G9: Sales | H9: =ROUND(N9/2,0) -> 87500 | I9: =ROUND(H9*40%,0) -> 35000 | J9: =N9-H9-I9-K9-L9-M9 -> 39000 | K9: 2000 | L9: 1000 | M9: =ROUND(H9*12%,0) -> 10500 | N9: =ROUND(O9/12,0) -> 175000 | O9: 2100000
A10: 9 | B10: ASG0009 | C10: 44893 | E10: Active | F10: Regional Sales Lead | G10: Sales | H10: =ROUND(N10/2,0) -> 75000 | I10: =ROUND(H10*40%,0) -> 30000 | J10: =N10-H10-I10-K10-L10-M10 -> 33000 | K10: 2000 | L10: 1000 | M10: =ROUND(H10*12%,0) -> 9000 | N10: =ROUND(O10/12,0) -> 150000 | O10: 1800000
A11: 10 | B11: ASG0010 | C11: 44907 | E11: Active | F11: Finance Manager | G11: Finance | H11: =ROUND(N11/2,0) -> 72917 | I11: =ROUND(H11*40%,0) -> 29167 | J11: =N11-H11-I11-K11-L11-M11 -> 31999 | K11: 2000 | L11: 1000 | M11: =ROUND(H11*12%,0) -> 8750 | N11: =ROUND(O11/12,0) -> 145833 | O11: 1750000
A12: 11 | B12: ASG0011 | C12: 44935 | D12: 45979 | E12: Relieved | F12: Regional Sales Lead | G12: Sales | H12: =ROUND(N12/2,0) -> 75000 | I12: =ROUND(H12*40%,0) -> 30000 | J12: =N12-H12-I12-K12-L12-M12 -> 33000 | K12: 2000 | L12: 1000 | M12: =ROUND(H12*12%,0) -> 9000 | N12: =ROUND(O12/12,0) -> 150000 | O12: 1800000
A13: 12 | B13: ASG0012 | C13: 44956 | E13: Active | F13: Senior Sales Executive | G13: Sales | H13: =ROUND(N13/2,0) -> 47917 | I13: =ROUND(H13*40%,0) -> 19167 | J13: =N13-H13-I13-K13-L13-M13 -> 19999 | K13: 2000 | L13: 1000 | M13: =ROUND(H13*12%,0) -> 5750 | N13: =ROUND(O13/12,0) -> 95833 | O13: 1150000
A14: 13 | B14: ASG0013 | C14: 44963 | E14: Active | F14: Senior Data Analyst | G14: Analytics | H14: =ROUND(N14/2,0) -> 64584 | I14: =ROUND(H14*40%,0) -> 25834 | J14: =N14-H14-I14-K14-L14-M14 -> 27999 | K14: 2000 | L14: 1000 | M14: =ROUND(H14*12%,0) -> 7750 | N14: =ROUND(O14/12,0) -> 129167 | O14: 1550000
A15: 14 | B15: ASG0014 | C15: 45005 | D15: 45919 | E15: Relieved | F15: Payroll Analyst | G15: Payroll | H15: =ROUND(N15/2,0) -> 27084 | I15: =ROUND(H15*40%,0) -> 10834 | J15: =N15-H15-I15-K15-L15-M15 -> 12999 | M15: =ROUND(H15*12%,0) -> 3250 | N15: =ROUND(O15/12,0) -> 54167 | O15: 650000
A16: 15 | B16: ASG0015 | C16: 45033 | E16: Active | F16: Senior Data Analyst | G16: Analytics | H16: =ROUND(N16/2,0) -> 61459 | I16: =ROUND(H16*40%,0) -> 24584 | J16: =N16-H16-I16-K16-L16-M16 -> 26499 | K16: 2000 | L16: 1000 | M16: =ROUND(H16*12%,0) -> 7375 | N16: =ROUND(O16/12,0) -> 122917 | O16: 1475000
A17: 16 | B17: ASG0016 | C17: 45040 | E17: Active | F17: Senior Data Analyst | G17: Analytics | H17: =ROUND(N17/2,0) -> 78125 | I17: =ROUND(H17*40%,0) -> 31250 | J17: =N17-H17-I17-K17-L17-M17 -> 34500 | K17: 2000 | L17: 1000 | M17: =ROUND(H17*12%,0) -> 9375 | N17: =ROUND(O17/12,0) -> 156250 | O17: 1875000
A18: 17 | B18: ASG0017 | C18: 45048 | D18: 46055 | E18: Relieved | F18: Sr Accountant | G18: Finance | H18: =ROUND(N18/2,0) -> 47917 | I18: =ROUND(H18*40%,0) -> 19167 | J18: =N18-H18-I18-K18-L18-M18 -> 19999 | K18: 2000 | L18: 1000 | M18: =ROUND(H18*12%,0) -> 5750 | N18: =ROUND(O18/12,0) -> 95833 | O18: 1150000
A19: 18 | B19: ASG0018 | C19: 45075 | E19: Active | F19: Sr Accountant | G19: Finance | H19: =ROUND(N19/2,0) -> 46875 | I19: =ROUND(H19*40%,0) -> 18750 | J19: =N19-H19-I19-K19-L19-M19 -> 19500 | K19: 2000 | L19: 1000 | M19: =ROUND(H19*12%,0) -> 5625 | N19: =ROUND(O19/12,0) -> 93750 | O19: 1125000
A20: 19 | B20: ASG0019 | C20: 45170 | E20: Active | F20: Senior Sales Executive | G20: Sales | H20: =ROUND(N20/2,0) -> 45834 | I20: =ROUND(H20*40%,0) -> 18334 | J20: =N20-H20-I20-K20-L20-M20 -> 18999 | K20: 2000 | L20: 1000 | M20: =ROUND(H20*12%,0) -> 5500 | N20: =ROUND(O20/12,0) -> 91667 | O20: 1100000
A21: 20 | B21: ASG0020 | C21: 45173 | E21: Active | F21: Sales Executive | G21: Sales | H21: =ROUND(N21/2,0) -> 32500 | I21: =ROUND(H21*40%,0) -> 13000 | J21: =N21-H21-I21-K21-L21-M21 -> 15600 | M21: =ROUND(H21*12%,0) -> 3900 | N21: =ROUND(O21/12,0) -> 65000 | O21: 780000
A22: 21 | B22: ASG0021 | C22: 45222 | D22: 45950 | E22: Relieved | F22: Payroll Analyst | G22: Payroll | H22: =ROUND(N22/2,0) -> 28125 | I22: =ROUND(H22*40%,0) -> 11250 | J22: =N22-H22-I22-K22-L22-M22 -> 13500 | M22: =ROUND(H22*12%,0) -> 3375 | N22: =ROUND(O22/12,0) -> 56250 | O22: 675000
A23: 22 | B23: ASG0022 | C23: 45236 | E23: Active | F23: Payroll Analyst | G23: Payroll | H23: =ROUND(N23/2,0) -> 28334 | I23: =ROUND(H23*40%,0) -> 11334 | J23: =N23-H23-I23-K23-L23-M23 -> 13599 | M23: =ROUND(H23*12%,0) -> 3400 | N23: =ROUND(O23/12,0) -> 56667 | O23: 680000
A24: 23 | B24: ASG0023 | C24: 45320 | E24: Active | F24: HR Analyst | G24: HR | H24: =ROUND(N24/2,0) -> 50000 | I24: =ROUND(H24*40%,0) -> 20000 | J24: =N24-H24-I24-K24-L24-M24 -> 21000 | K24: 2000 | L24: 1000 | M24: =ROUND(H24*12%,0) -> 6000 | N24: =ROUND(O24/12,0) -> 100000 | O24: 1200000
A25: 24 | B25: ASG0024 | C25: 45327 | D25: 46084 | E25: Relieved | F25: Accounts Executive | G25: Finance | H25: =ROUND(N25/2,0) -> 32500 | I25: =ROUND(H25*40%,0) -> 13000 | J25: =N25-H25-I25-K25-L25-M25 -> 15600 | M25: =ROUND(H25*12%,0) -> 3900 | N25: =ROUND(O25/12,0) -> 65000 | O25: 780000
A26: 25 | B26: ASG0025 | C26: 45328 | E26: Active | F26: Accounts Executive | G26: Finance | H26: =ROUND(N26/2,0) -> 30209 | I26: =ROUND(H26*40%,0) -> 12084 | J26: =N26-H26-I26-K26-L26-M26 -> 14499 | M26: =ROUND(H26*12%,0) -> 3625 | N26: =ROUND(O26/12,0) -> 60417 | O26: 725000
A27: 26 | B27: ASG0026 | C27: 45404 | D27: 46012 | E27: Relieved | F27: Sales Executive | G27: Sales | H27: =ROUND(N27/2,0) -> 34375 | I27: =ROUND(H27*40%,0) -> 13750 | J27: =N27-H27-I27-K27-L27-M27 -> 16500 | M27: =ROUND(H27*12%,0) -> 4125 | N27: =ROUND(O27/12,0) -> 68750 | O27: 825000
A28: 27 | B28: ASG0027 | C28: 45418 | E28: Active | F28: HR Analyst | G28: HR | H28: =ROUND(N28/2,0) -> 47917 | I28: =ROUND(H28*40%,0) -> 19167 | J28: =N28-H28-I28-K28-L28-M28 -> 19999 | K28: 2000 | L28: 1000 | M28: =ROUND(H28*12%,0) -> 5750 | N28: =ROUND(O28/12,0) -> 95833 | O28: 1150000
A29: 28 | B29: ASG0028 | C29: 45502 | E29: Active | F29: Sales Trainee | G29: Sales | H29: =ROUND(N29/2,0) -> 18750 | I29: =ROUND(H29*40%,0) -> 7500 | J29: =N29-H29-I29-K29-L29-M29 -> 9000 | M29: =ROUND(H29*12%,0) -> 2250 | N29: =ROUND(O29/12,0) -> 37500 | O29: 450000
A30: 29 | B30: ASG0029 | C30: 45509 | E30: Active | F30: Payroll Analyst | G30: Payroll | H30: =ROUND(N30/2,0) -> 27084 | I30: =ROUND(H30*40%,0) -> 10834 | J30: =N30-H30-I30-K30-L30-M30 -> 12999 | M30: =ROUND(H30*12%,0) -> 3250 | N30: =ROUND(O30/12,0) -> 54167 | O30: 650000
A31: 30 | B31: ASG0030 | C31: 45537 | D31: 46098 | E31: Relieved | F31: Senior Data Analyst | G31: Analytics | H31: =ROUND(N31/2,0) -> 59792 | I31: =ROUND(H31*40%,0) -> 23917 | J31: =N31-H31-I31-K31-L31-M31 -> 25699 | K31: 2000 | L31: 1000 | M31: =ROUND(H31*12%,0) -> 7175 | N31: =ROUND(O31/12,0) -> 119583 | O31: 1435000
A32: 31 | B32: ASG0031 | C32: 45579 | E32: Active | F32: Accounts Executive | G32: Finance | H32: =ROUND(N32/2,0) -> 29167 | I32: =ROUND(H32*40%,0) -> 11667 | J32: =N32-H32-I32-K32-L32-M32 -> 13999 | M32: =ROUND(H32*12%,0) -> 3500 | N32: =ROUND(O32/12,0) -> 58333 | O32: 700000
A33: 32 | B33: ASG0032 | C33: 45607 | E33: Active | F33: HR Executive | G33: HR | H33: =ROUND(N33/2,0) -> 31250 | I33: =ROUND(H33*40%,0) -> 12500 | J33: =N33-H33-I33-K33-L33-M33 -> 15000 | M33: =ROUND(H33*12%,0) -> 3750 | N33: =ROUND(O33/12,0) -> 62500 | O33: 750000
A34: 33 | B34: ASG0033 | C34: 45614 | E34: Active | F34: Data Analyst | G34: Analytics | H34: =ROUND(N34/2,0) -> 52084 | I34: =ROUND(H34*40%,0) -> 20834 | J34: =N34-H34-I34-K34-L34-M34 -> 21999 | K34: 2000 | L34: 1000 | M34: =ROUND(H34*12%,0) -> 6250 | N34: =ROUND(O34/12,0) -> 104167 | O34: 1250000
A35: 34 | B35: ASG0034 | C35: 45649 | D35: 46041 | E35: Relieved | F35: HR Executive | G35: HR | H35: =ROUND(N35/2,0) -> 26042 | I35: =ROUND(H35*40%,0) -> 10417 | J35: =N35-H35-I35-K35-L35-M35 -> 12499 | M35: =ROUND(H35*12%,0) -> 3125 | N35: =ROUND(O35/12,0) -> 52083 | O35: 625000
A36: 35 | B36: ASG0035 | C36: 45663 | E36: Active | F36: HR Executive | G36: HR | H36: =ROUND(N36/2,0) -> 25000 | I36: =ROUND(H36*40%,0) -> 10000 | J36: =N36-H36-I36-K36-L36-M36 -> 12000 | M36: =ROUND(H36*12%,0) -> 3000 | N36: =ROUND(O36/12,0) -> 50000 | O36: 600000
A37: 36 | B37: ASG0036 | C37: 45782 | E37: Active | F37: Payroll Executive | G37: Payroll | H37: =ROUND(N37/2,0) -> 19792 | I37: =ROUND(H37*40%,0) -> 7917 | J37: =N37-H37-I37-K37-L37-M37 -> 9499 | M37: =ROUND(H37*12%,0) -> 2375 | N37: =ROUND(O37/12,0) -> 39583 | O37: 475000
A38: 37 | B38: ASG0037 | C38: 45831 | D38: 46008 | E38: Relieved | F38: Accounts Trainee | G38: Finance | H38: =ROUND(N38/2,0) -> 18750 | I38: =ROUND(H38*40%,0) -> 7500 | J38: =N38-H38-I38-K38-L38-M38 -> 9000 | M38: =ROUND(H38*12%,0) -> 2250 | N38: =ROUND(O38/12,0) -> 37500 | O38: 450000
A39: 38 | B39: ASG0038 | C39: 45852 | E39: Active | F39: Accounts Trainee | G39: Finance | H39: =ROUND(N39/2,0) -> 18750 | I39: =ROUND(H39*40%,0) -> 7500 | J39: =N39-H39-I39-K39-L39-M39 -> 9000 | M39: =ROUND(H39*12%,0) -> 2250 | N39: =ROUND(O39/12,0) -> 37500 | O39: 450000
A40: 39 | B40: ASG0039 | C40: 45901 | E40: Active | F40: BI Developer | G40: Analytics | H40: =ROUND(N40/2,0) -> 53125 | I40: =ROUND(H40*40%,0) -> 21250 | J40: =N40-H40-I40-K40-L40-M40 -> 22500 | K40: 2000 | L40: 1000 | M40: =ROUND(H40*12%,0) -> 6375 | N40: =ROUND(O40/12,0) -> 106250 | O40: 1275000
...

Sheet Employee Headcount
A1: Year | B1: Month | C1: Department | D1: No.of Employees | E1: New Joiners | F1: Relievers | G1: Head Count
A2: 2022 | B2: February | C2: Analytics | D2: 0 | E2: 1 | F2: 0 | G2: 1
A3: 2022 | B3: February | C3: Finance | D3: 0 | E3: 0 | F3: 0 | G3: 0
A4: 2022 | B4: February | C4: HR | D4: 0 | E4: 1 | F4: 0 | G4: 1
A5: 2022 | B5: February | C5: Payroll | D5: 0 | E5: 0 | F5: 0 | G5: 0
A6: 2022 | B6: February | C6: Sales | D6: 0 | E6: 0 | F6: 0 | G6: 0
A7: 2022 | B7: March | C7: Analytics | D7: 1 | E7: 0 | F7: 0 | G7: 1
A8: 2022 | B8: March | C8: Finance | D8: 0 | E8: 0 | F8: 0 | G8: 0
A9: 2022 | B9: March | C9: HR | D9: 1 | E9: 1 | F9: 0 | G9: 2
A10: 2022 | B10: March | C10: Payroll | D10: 0 | E10: 0 | F10: 0 | G10: 0
A11: 2022 | B11: March | C11: Sales | D11: 0 | E11: 0 | F11: 0 | G11: 0
A12: 2022 | B12: April | C12: Analytics | D12: 1 | E12: 1 | F12: 0 | G12: 2
A13: 2022 | B13: April | C13: Finance | D13: 0 | E13: 0 | F13: 0 | G13: 0
... A251: 2026 | B251: March | C251: Sales | D251: 7 | E251: 1 | F251: 0 | G251: 8

Sheet Monthly Payroll
A1: Payroll Month | B1: Employee Id | C1: Date Of Joining | D1: Date of Leaving | E1: Designation | F1: Department | G1: Location | H1: LOP Days | I1: Pay Days | J1: OT Hours | K1: Basic | L1: HRA | M1: Special Allowance | N1: Fuel Allowance | O1: Internet Allowance | P1: Overtime Pay | Q1: Target Incentive | R1: Gross Salary | S1: Employee PF | T1: Income Tax | U1: Loan Deduction | V1: Net Salary
A2: 46023 | B2: ASG0001 | C2: 44593 | E2: HR Manager | F2: HR | G2: =VLOOKUP(tblPayroll[[#This Row],[Employee Id]],Table1[[Employee Id]:[Work Location]],13,0) -> Bangalore | H2: 6 | I2: =31-H2 -> 25 | J2: 0 | K2: =ROUND(VLOOKUP($B2,'CTC Breakup'!$B$2:$O$51,7,0)/31*$I2,0) -> 62165 | L2: =ROUND(VLOOKUP($B2,'CTC Breakup'!$B$2:$O$51,8,0)/31*$I2,0) -> 24866 | M2: =ROUND(VLOOKUP($B2,'CTC Breakup'!$B$2:$O$51,9,0)/31*$I2,0) -> 27419 | N2: =ROUND(VLOOKUP($B2,'CTC Breakup'!$B$2:$O$51,10,0)/31*$I2,0) -> 1613 | O2: =ROUND(VLOOKUP($B2,'CTC Breakup'!$B$2:$O$51,11,0)/31*$I2,0) -> 806 | P2: =ROUND(((VLOOKUP($B2,'CTC Breakup'!$B$2:$N$51,13,0)-VLOOKUP($B2,'CTC Breakup'!$B$2:$N$51,12,0))/22/9)*$J2,0) -> 0 | Q2: 0 | R2: =SUM(K2:Q2) -> 116869 | S2: =ROUND(K2*12%,0) -> 7460 | T2: =ROUND(IF(R2>100000,R2*30%,IF(R2>75000,R2*20%,IF(R2>50000,R2*5%,0))),0) -> 35061 | U2: 0 | V2: =R2-S2-T2-U2 -> 74348 | X2: Total Net Salary for Q4 | Y2: =SUM(tblPayroll[Net Salary]) -> 6810287
A3: 46023 | B3: ASG0002 | C3: 44613 | E3: Analytics Manager | F3: Analytics | G3: =VLOOKUP(tblPayroll[[#This Row],[Employee Id]],Table1[[Employee Id]:[Work Location]],13,0) -> Chennai | H3: 10 | I3: =31-H3 -> 21 | J3: 0 | K3: =ROUND(VLOOKUP($B3,'CTC Breakup'!$B$2:$O$51,7,0)/31*$I3,0) -> 70565 | L3: =ROUND(VLOOKUP($B3,'CTC Breakup'!$B$2:$O$51,8,0)/31*$I3,0) -> 28226 | M3: =ROUND(VLOOKUP($B3,'CTC Breakup'!$B$2:$O$51,9,0)/31*$I3,0) -> 33870 | N3: =ROUND(VLOOKUP($B3,'CTC Breakup'!$B$2:$O$51,10,0)/31*$I3,0) -> 0 | O3: =ROUND(VLOOKUP($B3,'CTC Breakup'!$B$2:$O$51,11,0)/31*$I3,0) -> 0 | P3: =ROUND(((VLOOKUP($B3,'CTC Breakup'!$B$2:$N$51,13,0)-VLOOKUP($B3,'CTC Breakup'!$B$2:$N$51,12,0))/22/9)*$J3,0) -> 0 | Q3: 0 | R3: =SUM(K3:Q3) -> 132661 | S3: =ROUND(K3*12%,0) -> 8468 | T3: =ROUND(IF(R3>100000,R3*30%,IF(R3>75000,R3*20%,IF(R3>50000,R3*5%,0))),0) -> 39798 | U3: 0 | V3: =R3-S3-T3-U3 -> 84395
A4: 46023 | B4: ASG0003 | C4: 44634 | E4: HR Manager | F4: HR | G4: =VLOOKUP(tblPayroll[[#This Row],[Employee Id]],Table1[[Employee Id]:[Work Location]],13,0) -> Bangalore | H4: 0 | I4: =31-H4 -> 31 | J4: 24 | K4: =ROUND(VLOOKUP($B4,'CTC Breakup'!$B$2:$O$51,7,0)/31*$I4,0) -> 72917 | L4: =ROUND(VLOOKUP($B4,'CTC Breakup'!$B$2:$O$51,8,0)/31*$I4,0) -> 29167 | M4: =ROUND(VLOOKUP($B4,'CTC Breakup'!$B$2:$O$51,9,0)/31*$I4,0) -> 31999 | N4: =ROUND(VLOOKUP($B4,'CTC Breakup'!$B$2:$O$51,10,0)/31*$I4,0) -> 2000 | O4: =ROUND(VLOOKUP($B4,'CTC Breakup'!$B$2:$O$51,11,0)/31*$I4,0) -> 1000 | P4: =ROUND(((VLOOKUP($B4,'CTC Breakup'!$B$2:$N$51,13,0)-VLOOKUP($B4,'CTC Breakup'!$B$2:$N$51,12,0))/22/9)*$J4,0) -> 16616 | Q4: 0 | R4: =SUM(K4:Q4) -> 153699 | S4: =ROUND(K4*12%,0) -> 8750 | T4: =ROUND(IF(R4>100000,R4*30%,IF(R4>75000,R4*20%,IF(R4>50000,R4*5%,0))),0) -> 46110 | U4: 0 | V4: =R4-S4-T4-U4 -> 98839 | X4: Gross Salary Paid | Y4: =SUM(tblPayroll[Gross Salary]) -> 9636624
A5: 46023 | B5: ASG0005 | C5: 44697 | E5: Payroll Manager | F5: Payroll | G5: =VLOOKUP(tblPayroll[[#This Row],[Employee Id]],Table1[[Employee Id]:[Work Location]],13,0) -> Chennai | H5: 7 | I5: =31-H5 -> 24 | J5: 17 | K5: =ROUND(VLOOKUP($B5,'CTC Breakup'!$B$2:$O$51,7,0)/31*$I5,0) -> 54839 | L5: =ROUND(VLOOKUP($B5,'CTC Breakup'!$B$2:$O$51,8,0)/31*$I5,0) -> 21936 | M5: =ROUND(VLOOKUP($B5,'CTC Breakup'!$B$2:$O$51,9,0)/31*$I5,0) -> 23999 | N5: =ROUND(VLOOKUP($B5,'CTC Breakup'!$B$2:$O$51,10,0)/31*$I5,0) -> 1548 | O5: =ROUND(VLOOKUP($B5,'CTC Breakup'!$B$2:$O$51,11,0)/31*$I5,0) -> 774 | P5: =ROUND(((VLOOKUP($B5,'CTC Breakup'!$B$2:$N$51,13,0)-VLOOKUP($B5,'CTC Breakup'!$B$2:$N$51,12,0))/22/9)*$J5,0) -> 11434 | Q5: 0 | R5: =SUM(K5:Q5) -> 114530 | S5: =ROUND(K5*12%,0) -> 6581 | T5: =ROUND(IF(R5>100000,R5*30%,IF(R5>75000,R5*20%,IF(R5>50000,R5*5%,0))),0) -> 34359 | U5: 0 | V5: =R5-S5-T5-U5 -> 73590
A6: 46023 | B6: ASG0006 | C6: 44704 | E6: Senior Payroll Analyst | F6: Payroll | G6: =VLOOKUP(tblPayroll[[#This Row],[Employee Id]],Table1[[Employee Id]:[Work Location]],13,0) -> Mumbai | H6: 0 | I6: =31-H6 -> 31 | J6: 0 | K6: =ROUND(VLOOKUP($B6,'CTC Breakup'!$B$2:$O$51,7,0)/31*$I6,0) -> 41667 | L6: =ROUND(VLOOKUP($B6,'CTC Breakup'!$B$2:$O$51,8,0)/31*$I6,0) -> 16667 | M6: =ROUND(VLOOKUP($B6,'CTC Breakup'!$B$2:$O$51,9,0)/31*$I6,0) -> 16999 | N6: =ROUND(VLOOKUP($B6,'CTC Breakup'!$B$2:$O$51,10,0)/31*$I6,0) -> 2000 | O6: =ROUND(VLOOKUP($B6,'CTC Breakup'!$B$2:$O$51,11,0)/31*$I6,0) -> 1000 | P6: =ROUND(((VLOOKUP($B6,'CTC Breakup'!$B$2:$N$51,13,0)-VLOOKUP($B6,'CTC Breakup'!$B$2:$N$51,12,0))/22/9)*$J6,0) -> 0 | Q6: 0 | R6: =SUM(K6:Q6) -> 78333 | S6: =ROUND(K6*12%,0) -> 5000 | T6: =ROUND(IF(R6>100000,R6*30%,IF(R6>75000,R6*20%,IF(R6>50000,R6*5%,0))),0) -> 15667 | U6: 12500 | V6: =R6-S6-T6-U6 -> 45166 | X6: Total OT Hours | Y6: =SUM(tblPayroll[OT Hours]) -> 946
A7: 46023 | B7: ASG0008 | C7: 44886 | E7: Sales Manager | F7: Sales | G7: =VLOOKUP(tblPayroll[[#This Row],[Employee Id]],Table1[[Employee Id]:[Work Location]],13,0) -> Kolkata | H7: 0 | I7: =31-H7 -> 31 | J7: 20 | K7: =ROUND(VLOOKUP($B7,'CTC Breakup'!$B$2:$O$51,7,0)/31*$I7,0) -> 87500 | L7: =ROUND(VLOOKUP($B7,'CTC Breakup'!$B$2:$O$51,8,0)/31*$I7,0) -> 35000 | M7: =ROUND(VLOOKUP($B7,'CTC Breakup'!$B$2:$O$51,9,0)/31*$I7,0) -> 39000 | N7: =ROUND(VLOOKUP($B7,'CTC Breakup'!$B$2:$O$51,10,0)/31*$I7,0) -> 2000 | O7: =ROUND(VLOOKUP($B7,'CTC Breakup'!$B$2:$O$51,11,0)/31*$I7,0) -> 1000 | P7: =ROUND(((VLOOKUP($B7,'CTC Breakup'!$B$2:$N$51,13,0)-VLOOKUP($B7,'CTC Breakup'!$B$2:$N$51,12,0))/22/9)*$J7,0) -> 16616 | Q7: 31000 | R7: =SUM(K7:Q7) -> 212116 | S7: =ROUND(K7*12%,0) -> 10500 | T7: =ROUND(IF(R7>100000,R7*30%,IF(R7>75000,R7*20%,IF(R7>50000,R7*5%,0))),0) -> 63635 | U7: 0 | V7: =R7-S7-T7-U7 -> 137981
A8: 46023 | B8: ASG0009 | C8: 44893 | E8: Regional Sales Lead | F8: Sales | G8: =VLOOKUP(tblPayroll[[#This Row],[Employee Id]],Table1[[Employee Id]:[Work Location]],13,0) -> Hyderabad | H8: 0 | I8: =31-H8 -> 31 | J8: 19 | K8: =ROUND(VLOOKUP($B8,'CTC Breakup'!$B$2:$O$51,7,0)/31*$I8,0) -> 75000 | L8: =ROUND(VLOOKUP($B8,'CTC Breakup'!$B$2:$O$51,8,0)/31*$I8,0) -> 30000 | M8: =ROUND(VLOOKUP($B8,'CTC Breakup'!$B$2:$O$51,9,0)/31*$I8,0) -> 33000 | N8: =ROUND(VLOOKUP($B8,'CTC Breakup'!$B$2:$O$51,10,0)/31*$I8,0) -> 2000 | O8: =ROUND(VLOOKUP($B8,'CTC Breakup'!$B$2:$O$51,11,0)/31*$I8,0) -> 1000 | P8: =ROUND(((VLOOKUP($B8,'CTC Breakup'!$B$2:$N$51,13,0)-VLOOKUP($B8,'CTC Breakup'!$B$2:$N$51,12,0))/22/9)*$J8,0) -> 13530 | Q8: 27500 | R8: =SUM(K8:Q8) -> 182030 | S8: =ROUND(K8*12%,0) -> 9000 | T8: =ROUND(IF(R8>100000,R8*30%,IF(R8>75000,R8*20%,IF(R8>50000,R8*5%,0))),0) -> 54609 | U8: 0 | V8: =R8-S8-T8-U8 -> 118421 | X8: Total LOP Days | Y8: =SUM(tblPayroll[LOP Days]) -> 269
A9: 46023 | B9: ASG0010 | C9: 44907 | E9: Finance Manager | F9: Finance | G9: =VLOOKUP(tblPayroll[[#This Row],[Employee Id]],Table1[[Employee Id]:[Work Location]],13,0) -> Mumbai | H9: 0 | I9: =31-H9 -> 31 | J9: 0 | K9: =ROUND(VLOOKUP($B9,'CTC Breakup'!$B$2:$O$51,7,0)/31*$I9,0) -> 72917 | L9: =ROUND(VLOOKUP($B9,'CTC Breakup'!$B$2:$O$51,8,0)/31*$I9,0) -> 29167 | M9: =ROUND(VLOOKUP($B9,'CTC Breakup'!$B$2:$O$51,9,0)/31*$I9,0) -> 31999 | N9: =ROUND(VLOOKUP($B9,'CTC Breakup'!$B$2:$O$51,10,0)/31*$I9,0) -> 2000 | O9: =ROUND(VLOOKUP($B9,'CTC Breakup'!$B$2:$O$51,11,0)/31*$I9,0) -> 1000 | P9: =ROUND(((VLOOKUP($B9,'CTC Breakup'!$B$2:$N$51,13,0)-VLOOKUP($B9,'CTC Breakup'!$B$2:$N$51,12,0))/22/9)*$J9,0) -> 0 | Q9: 0 | R9: =SUM(K9:Q9) -> 137083 | S9: =ROUND(K9*12%,0) -> 8750 | T9: =ROUND(IF(R9>100000,R9*30%,IF(R9>75000,R9*20%,IF(R9>50000,R9*5%,0))),0) -> 41125 | U9: 0 | V9: =R9-S9-T9-U9 -> 87208
A10: 46023 | B10: ASG0012 | C10: 44956 | E10: Senior Sales Executive | F10: Sales | G10: =VLOOKUP(tblPayroll[[#This Row],[Employee Id]],Table1[[Employee Id]:[Work Location]],13,0) -> Chennai | H10: 6 | I10: =31-H10 -> 25 | J10: 0 | K10: =ROUND(VLOOKUP($B10,'CTC Breakup'!$B$2:$O$51,7,0)/31*$I10,0) -> 38643 | L10: =ROUND(VLOOKUP($B10,'CTC Breakup'!$B$2:$O$51,8,0)/31*$I10,0) -> 15457 | M10: =ROUND(VLOOKUP($B10,'CTC Breakup'!$B$2:$O$51,9,0)/31*$I10,0) -> 16128 | N10: =ROUND(VLOOKUP($B10,'CTC Breakup'!$B$2:$O$51,10,0)/31*$I10,0) -> 1613 | O10: =ROUND(VLOOKUP($B10,'CTC Breakup'!$B$2:$O$51,11,0)/31*$I10,0) -> 806 | P10: =ROUND(((VLOOKUP($B10,'CTC Breakup'!$B$2:$N$51,13,0)-VLOOKUP($B10,'CTC Breakup'!$B$2:$N$51,12,0))/22/9)*$J10,0) -> 0 | Q10: 21400 | R10: =SUM(K10:Q10) -> 94047 | S10: =ROUND(K10*12%,0) -> 4637 | T10: =ROUND(IF(R10>100000,R10*30%,IF(R10>75000,R10*20%,IF(R10>50000,R10*5%,0))),0) -> 18809 | U10: 0 | V10: =R10-S10-T10-U10 -> 70601 | X10: Costliest Location | Y10: =INDEX($G$2:$G$117, MATCH(MAX($V$2:$V$117), $V$2:$V$117, 0)) -> Kolkata
A11: 46023 | B11: ASG0013 | C11: 44963 | E11: Senior Data Analyst | F11: Analytics | G11: =VLOOKUP(tblPayroll[[#This Row],[Employee Id]],Table1[[Employee Id]:[Work Location]],13,0) -> Bangalore | H11: 0 | I11: =31-H11 -> 31 | J11: 0 | K11: =ROUND(VLOOKUP($B11,'CTC Breakup'!$B$2:$O$51,7,0)/31*$I11,0) -> 64584 | L11: =ROUND(VLOOKUP($B11,'CTC Breakup'!$B$2:$O$51,8,0)/31*$I11,0) -> 25834 | M11: =ROUND(VLOOKUP($B11,'CTC Breakup'!$B$2:$O$51,9,0)/31*$I11,0) -> 27999 | N11: =ROUND(VLOOKUP($B11,'CTC Breakup'!$B$2:$O$51,10,0)/31*$I11,0) -> 2000 | O11: =ROUND(VLOOKUP($B11,'CTC Breakup'!$B$2:$O$51,11,0)/31*$I11,0) -> 1000 | P11: =ROUND(((VLOOKUP($B11,'CTC Breakup'!$B$2:$N$51,13,0)-VLOOKUP($B11,'CTC Breakup'!$B$2:$N$51,12,0))/22/9)*$J11,0) -> 0 | Q11: 0 | R11: =SUM(K11:Q11) -> 121417 | S11: =ROUND(K11*12%,0) -> 7750 | T11: =ROUND(IF(R11>100000,R11*30%,IF(R11>75000,R11*20%,IF(R11>50000,R11*5%,0))),0) -> 36425 | U11: 0 | V11: =R11-S11-T11-U11 -> 77242
A12: 46023 | B12: ASG0015 | C12: 45033 | E12: Senior Data Analyst | F12: Analytics | G12: =VLOOKUP(tblPayroll[[#This Row],[Employee Id]],Table1[[Employee Id]:[Work Location]],13,0) -> Hyderabad | H12: 0 | I12: =31-H12 -> 31 | J12: 0 | K12: =ROUND(VLOOKUP($B12,'CTC Breakup'!$B$2:$O$51,7,0)/31*$I12,0) -> 61459 | L12: =ROUND(VLOOKUP($B12,'CTC Breakup'!$B$2:$O$51,8,0)/31*$I12,0) -> 24584 | M12: =ROUND(VLOOKUP($B12,'CTC Breakup'!$B$2:$O$51,9,0)/31*$I12,0) -> 26499 | N12: =ROUND(VLOOKUP($B12,'CTC Breakup'!$B$2:$O$51,10,0)/31*$I12,0) -> 2000 | O12: =ROUND(VLOOKUP($B12,'CTC Breakup'!$B$2:$O$51,11,0)/31*$I12,0) -> 1000 | P12: =ROUND(((VLOOKUP($B12,'CTC Breakup'!$B$2:$N$51,13,0)-VLOOKUP($B12,'CTC Breakup'!$B$2:$N$51,12,0))/22/9)*$J12,0) -> 0 | Q12: 0 | R12: =SUM(K12:Q12) -> 115542 | S12: =ROUND(K12*12%,0) -> 7375 | T12: =ROUND(IF(R12>100000,R12*30%,IF(R12>75000,R12*20%,IF(R12>50000,R12*5%,0))),0) -> 34663 | U12: 0 | V12: =R12-S12-T12-U12 -> 73504 | X12: Costliest Department | Y12: =INDEX($F$2:$F$117, MATCH(MAX($V$2:$V$117), $V$2:$V$117, 0)) -> Sales
A13: 46023 | B13: ASG0016 | C13: 45040 | E13: Senior Data Analyst | F13: Analytics | G13: =VLOOKUP(tblPayroll[[#This Row],[Employee Id]],Table1[[Employee Id]:[Work Location]],13,0) -> Bangalore | H13: 0 | I13: =31-H13 -> 31 | J13: 16 | K13: =ROUND(VLOOKUP($B13,'CTC Breakup'!$B$2:$O$51,7,0)/31*$I13,0) -> 78125 | L13: =ROUND(VLOOKUP($B13,'CTC Breakup'!$B$2:$O$51,8,0)/31*$I13,0) -> 31250 | M13: =ROUND(VLOOKUP($B13,'CTC Breakup'!$B$2:$O$51,9,0)/31*$I13,0) -> 34500 | N13: =ROUND(VLOOKUP($B13,'CTC Breakup'!$B$2:$O$51,10,0)/31*$I13,0) -> 2000 | O13: =ROUND(VLOOKUP($B13,'CTC Breakup'!$B$2:$O$51,11,0)/31*$I13,0) -> 1000 | P13: =ROUND(((VLOOKUP($B13,'CTC Breakup'!$B$2:$N$51,13,0)-VLOOKUP($B13,'CTC Breakup'!$B$2:$N$51,12,0))/22/9)*$J13,0) -> 11869 | Q13: 0 | R13: =SUM(K13:Q13) -> 158744 | S13: =ROUND(K13*12%,0) -> 9375 | T13: =ROUND(IF(R13>100000,R13*30%,IF(R13>75000,R13*20%,IF(R13>50000,R13*5%,0))),0) -> 47623 | U13: 0 | V13: =R13-S13-T13-U13 -> 101746
A14: 46023 | B14: ASG0017 | C14: 45048 | D14: 46055 | E14: Sr Accountant | F14: Finance | G14: =VLOOKUP(tblPayroll[[#This Row],[Employee Id]],Table1[[Employee Id]:[Work Location]],13,0) -> Chennai | H14: 6 | I14: =31-H14 -> 25 | J14: 0 | K14: =ROUND(VLOOKUP($B14,'CTC Breakup'!$B$2:$O$51,7,0)/31*$I14,0) -> 38643 | L14: =ROUND(VLOOKUP($B14,'CTC Breakup'!$B$2:$O$51,8,0)/31*$I14,0) -> 15457 | M14: =ROUND(VLOOKUP($B14,'CTC Breakup'!$B$2:$O$51,9,0)/31*$I14,0) -> 16128 | N14: =ROUND(VLOOKUP($B14,'CTC Breakup'!$B$2:$O$51,10,0)/31*$I14,0) -> 1613 | O14: =ROUND(VLOOKUP($B14,'CTC Breakup'!$B$2:$O$51,11,0)/31*$I14,0) -> 806 | P14: =ROUND(((VLOOKUP($B14,'CTC Breakup'!$B$2:$N$51,13,0)-VLOOKUP($B14,'CTC Breakup'!$B$2:$N$51,12,0))/22/9)*$J14,0) -> 0 | Q14: 0 | R14: =SUM(K14:Q14) -> 72647 | S14: =ROUND(K14*12%,0) -> 4637 | T14: =ROUND(IF(R14>100000,R14*30%,IF(R14>75000,R14*20%,IF(R14>50000,R14*10%,0))),0) -> 7265 | U14: 0 | V14: =R14-S14-T14-U14 -> 60745
A15: 46023 | B15: ASG0018 | C15: 45075 | E15: Sr Accountant | F15: Finance | G15: =VLOOKUP(tblPayroll[[#This Row],[Employee Id]],Table1[[Employee Id]:[Work Location]],13,0) -> Bangalore | H15: 7 | I15: =31-H15 -> 24 | J15: 0 | K15: =ROUND(VLOOKUP($B15,'CTC Breakup'!$B$2:$O$51,7,0)/31*$I15,0) -> 36290 | L15: =ROUND(VLOOKUP($B15,'CTC Breakup'!$B$2:$O$51,8,0)/31*$I15,0) -> 14516 | M15: =ROUND(VLOOKUP($B15,'CTC Breakup'!$B$2:$O$51,9,0)/31*$I15,0) -> 15097 | N15: =ROUND(VLOOKUP($B15,'CTC Breakup'!$B$2:$O$51,10,0)/31*$I15,0) -> 1548 | O15: =ROUND(VLOOKUP($B15,'CTC Breakup'!$B$2:$O$51,11,0)/31*$I15,0) -> 774 | P15: =ROUND(((VLOOKUP($B15,'CTC Breakup'!$B$2:$N$51,13,0)-VLOOKUP($B15,'CTC Breakup'!$B$2:$N$51,12,0))/22/9)*$J15,0) -> 0 | Q15: 0 | R15: =SUM(K15:Q15) -> 68225 | S15: =ROUND(K15*12%,0) -> 4355 | T15: =ROUND(IF(R15>100000,R15*30%,IF(R15>75000,R15*20%,IF(R15>50000,R15*10%,0))),0) -> 6823 | U15: 12400 | V15: =R15-S15-T15-U15 -> 44647
A16: 46023 | B16: ASG0019 | C16: 45170 | E16: Senior Sales Executive | F16: Sales | G16: =VLOOKUP(tblPayroll[[#This Row],[Employee Id]],Table1[[Employee Id]:[Work Location]],13,0) -> Mumbai | H16: 0 | I16: =31-H16 -> 31 | J16: 0 | K16: =ROUND(VLOOKUP($B16,'CTC Breakup'!$B$2:$O$51,7,0)/31*$I16,0) -> 45834 | L16: =ROUND(VLOOKUP($B16,'CTC Breakup'!$B$2:$O$51,8,0)/31*$I16,0) -> 18334 | M16: =ROUND(VLOOKUP($B16,'CTC Breakup'!$B$2:$O$51,9,0)/31*$I16,0) -> 18999 | N16: =ROUND(VLOOKUP($B16,'CTC Breakup'!$B$2:$O$51,10,0)/31*$I16,0) -> 2000 | O16: =ROUND(VLOOKUP($B16,'CTC Breakup'!$B$2:$O$51,11,0)/31*$I16,0) -> 1000 | P16: =ROUND(((VLOOKUP($B16,'CTC Breakup'!$B$2:$N$51,13,0)-VLOOKUP($B16,'CTC Breakup'!$B$2:$N$51,12,0))/22/9)*$J16,0) -> 0 | Q16: 20740 | R16: =SUM(K16:Q16) -> 106907 | S16: =ROUND(K16*12%,0) -> 5500 | T16: =ROUND(IF(R16>100000,R16*30%,IF(R16>75000,R16*20%,IF(R16>50000,R16*5%,0))),0) -> 32072 | U16: 11200 | V16: =R16-S16-T16-U16 -> 58135
A17: 46023 | B17: ASG0020 | C17: 45173 | E17: Sales Executive | F17: Sales | G17: =VLOOKUP(tblPayroll[[#This Row],[Employee Id]],Table1[[Employee Id]:[Work Location]],13,0) -> Kolkata | H17: 9 | I17: =31-H17 -> 22 | J17: 0 | K17: =ROUND(VLOOKUP($B17,'CTC Breakup'!$B$2:$O$51,7,0)/31*$I17,0) -> 23065 | L17: =ROUND(VLOOKUP($B17,'CTC Breakup'!$B$2:$O$51,8,0)/31*$I17,0) -> 9226 | M17: =ROUND(VLOOKUP($B17,'CTC Breakup'!$B$2:$O$51,9,0)/31*$I17,0) -> 11071 | N17: =ROUND(VLOOKUP($B17,'CTC Breakup'!$B$2:$O$51,10,0)/31*$I17,0) -> 0 | O17: =ROUND(VLOOKUP($B17,'CTC Breakup'!$B$2:$O$51,11,0)/31*$I17,0) -> 0 | P17: =ROUND(((VLOOKUP($B17,'CTC Breakup'!$B$2:$N$51,13,0)-VLOOKUP($B17,'CTC Breakup'!$B$2:$N$51,12,0))/22/9)*$J17,0) -> 0 | Q17: 14300 | R17: =SUM(K17:Q17) -> 57662 | S17: =ROUND(K17*12%,0) -> 2768 | T17: =ROUND(IF(R17>100000,R17*30%,IF(R17>75000,R17*20%,IF(R17>50000,R17*10%,0))),0) -> 5766 | U17: 0 | V17: =R17-S17-T17-U17 -> 49128
A18: 46023 | B18: ASG0022 | C18: 45236 | E18: Payroll Analyst | F18: Payroll | G18: =VLOOKUP(tblPayroll[[#This Row],[Employee Id]],Table1[[Employee Id]:[Work Location]],13,0) -> Mumbai | H18: 0 | I18: =31-H18 -> 31 | J18: 24 | K18: =ROUND(VLOOKUP($B18,'CTC Breakup'!$B$2:$O$51,7,0)/31*$I18,0) -> 28334 | L18: =ROUND(VLOOKUP($B18,'CTC Breakup'!$B$2:$O$51,8,0)/31*$I18,0) -> 11334 | M18: =ROUND(VLOOKUP($B18,'CTC Breakup'!$B$2:$O$51,9,0)/31*$I18,0) -> 13599 | N18: =ROUND(VLOOKUP($B18,'CTC Breakup'!$B$2:$O$51,10,0)/31*$I18,0) -> 0 | O18: =ROUND(VLOOKUP($B18,'CTC Breakup'!$B$2:$O$51,11,0)/31*$I18,0) -> 0 | P18: =ROUND(((VLOOKUP($B18,'CTC Breakup'!$B$2:$N$51,13,0)-VLOOKUP($B18,'CTC Breakup'!$B$2:$N$51,12,0))/22/9)*$J18,0) -> 6457 | Q18: 0 | R18: =SUM(K18:Q18) -> 59724 | S18: =ROUND(K18*12%,0) -> 3400 | T18: =ROUND(IF(R18>100000,R18*30%,IF(R18>75000,R18*20%,IF(R18>50000,R18*10%,0))),0) -> 5972 | U18: 0 | V18: =R18-S18-T18-U18 -> 50352
A19: 46023 | B19: ASG0023 | C19: 45320 | E19: HR Analyst | F19: HR | G19: =VLOOKUP(tblPayroll[[#This Row],[Employee Id]],Table1[[Employee Id]:[Work Location]],13,0) -> Hyderabad | H19: 6 | I19: =31-H19 -> 25 | J19: 0 | K19: =ROUND(VLOOKUP($B19,'CTC Breakup'!$B$2:$O$51,7,0)/31*$I19,0) -> 40323 | L19: =ROUND(VLOOKUP($B19,'CTC Breakup'!$B$2:$O$51,8,0)/31*$I19,0) -> 16129 | M19: =ROUND(VLOOKUP($B19,'CTC Breakup'!$B$2:$O$51,9,0)/31*$I19,0) -> 16935 | N19: =ROUND(VLOOKUP($B19,'CTC Breakup'!$B$2:$O$51,10,0)/31*$I19,0) -> 1613 | O19: =ROUND(VLOOKUP($B19,'CTC Breakup'!$B$2:$O$51,11,0)/31*$I19,0) -> 806 | P19: =ROUND(((VLOOKUP($B19,'CTC Breakup'!$B$2:$N$51,13,0)-VLOOKUP($B19,'CTC Breakup'!$B$2:$N$51,12,0))/22/9)*$J19,0) -> 0 | Q19: 0 | R19: =SUM(K19:Q19) -> 75806 | S19: =ROUND(K19*12%,0) -> 4839 | T19: =ROUND(IF(R19>100000,R19*30%,IF(R19>75000,R19*20%,IF(R19>50000,R19*5%,0))),0) -> 15161 | U19: 13800 | V19: =R19-S19-T19-U19 -> 42006
A20: 46023 | B20: ASG0024 | C20: 45327 | D20: 46084 | E20: Accounts Executive | F20: Finance | G20: =VLOOKUP(tblPayroll[[#This Row],[Employee Id]],Table1[[Employee Id]:[Work Location]],13,0) -> Kolkata | H20: 0 | I20: =31-H20 -> 31 | J20: 0 | K20: =ROUND(VLOOKUP($B20,'CTC Breakup'!$B$2:$O$51,7,0)/31*$I20,0) -> 32500 | L20: =ROUND(VLOOKUP($B20,'CTC Breakup'!$B$2:$O$51,8,0)/31*$I20,0) -> 13000 | M20: =ROUND(VLOOKUP($B20,'CTC Breakup'!$B$2:$O$51,9,0)/31*$I20,0) -> 15600 | N20: =ROUND(VLOOKUP($B20,'CTC Breakup'!$B$2:$O$51,10,0)/31*$I20,0) -> 0 | O20: =ROUND(VLOOKUP($B20,'CTC Breakup'!$B$2:$O$51,11,0)/31*$I20,0) -> 0 | P20: =ROUND(((VLOOKUP($B20,'CTC Breakup'!$B$2:$N$51,13,0)-VLOOKUP($B20,'CTC Breakup'!$B$2:$N$51,12,0))/22/9)*$J20,0) -> 0 | Q20: 0 | R20: =SUM(K20:Q20) -> 61100 | S20: =ROUND(K20*12%,0) -> 3900 | T20: =ROUND(IF(R20>100000,R20*30%,IF(R20>75000,R20*20%,IF(R20>50000,R20*10%,0))),0) -> 6110 | U20: 0 | V20: =R20-S20-T20-U20 -> 51090
A21: 46023 | B21: ASG0025 | C21: 45328 | E21: Accounts Executive | F21: Finance | G21: =VLOOKUP(tblPayroll[[#This Row],[Employee Id]],Table1[[Employee Id]:[Work Location]],13,0) -> Chennai | H21: 0 | I21: =31-H21 -> 31 | J21: 0 | K21: =ROUND(VLOOKUP($B21,'CTC Breakup'!$B$2:$O$51,7,0)/31*$I21,0) -> 30209 | L21: =ROUND(VLOOKUP($B21,'CTC Breakup'!$B$2:$O$51,8,0)/31*$I21,0) -> 12084 | M21: =ROUND(VLOOKUP($B21,'CTC Breakup'!$B$2:$O$51,9,0)/31*$I21,0) -> 14499 | N21: =ROUND(VLOOKUP($B21,'CTC Breakup'!$B$2:$O$51,10,0)/31*$I21,0) -> 0 | O21: =ROUND(VLOOKUP($B21,'CTC Breakup'!$B$2:$O$51,11,0)/31*$I21,0) -> 0 | P21: =ROUND(((VLOOKUP($B21,'CTC Breakup'!$B$2:$N$51,13,0)-VLOOKUP($B21,'CTC Breakup'!$B$2:$N$51,12,0))/22/9)*$J21,0) -> 0 | Q21: 0 | R21: =SUM(K21:Q21) -> 56792 | S21: =ROUND(K21*12%,0) -> 3625 | T21: =ROUND(IF(R21>100000,R21*30%,IF(R21>75000,R21*20%,IF(R21>50000,R21*10%,0))),0) -> 5679 | U21: 0 | V21: =R21-S21-T21-U21 -> 47488
A22: 46023 | B22: ASG0027 | C22: 45418 | E22: HR Analyst | F22: HR | G22: =VLOOKUP(tblPayroll[[#This Row],[Employee Id]],Table1[[Employee Id]:[Work Location]],13,0) -> Mumbai | H22: 0 | I22: =31-H22 -> 31 | J22: 0 | K22: =ROUND(VLOOKUP($B22,'CTC Breakup'!$B$2:$O$51,7,0)/31*$I22,0) -> 47917 | L22: =ROUND(VLOOKUP($B22,'CTC Breakup'!$B$2:$O$51,8,0)/31*$I22,0) -> 19167 | M22: =ROUND(VLOOKUP($B22,'CTC Breakup'!$B$2:$O$51,9,0)/31*$I22,0) -> 19999 | N22: =ROUND(VLOOKUP($B22,'CTC Breakup'!$B$2:$O$51,10,0)/31*$I22,0) -> 2000 | O22: =ROUND(VLOOKUP($B22,'CTC Breakup'!$B$2:$O$51,11,0)/31*$I22,0) -> 1000 | P22: =ROUND(((VLOOKUP($B22,'CTC Breakup'!$B$2:$N$51,13,0)-VLOOKUP($B22,'CTC Breakup'!$B$2:$N$51,12,0))/22/9)*$J22,0) -> 0 | Q22: 0 | R22: =SUM(K22:Q22) -> 90083 | S22: =ROUND(K22*12%,0) -> 5750 | T22: =ROUND(IF(R22>100000,R22*30%,IF(R22>75000,R22*20%,IF(R22>50000,R22*5%,0))),0) -> 18017 | U22: 0 | V22: =R22-S22-T22-U22 -> 66316
A23: 46023 | B23: ASG0028 | C23: 45502 | E23: Sales Trainee | F23: Sales | G23: =VLOOKUP(tblPayroll[[#This Row],[Employee Id]],Table1[[Employee Id]:[Work Location]],13,0) -> Hyderabad | H23: 0 | I23: =31-H23 -> 31 | J23: 17 | K23: =ROUND(VLOOKUP($B23,'CTC Breakup'!$B$2:$O$51,7,0)/31*$I23,0) -> 18750 | L23: =ROUND(VLOOKUP($B23,'CTC Breakup'!$B$2:$O$51,8,0)/31*$I23,0) -> 7500 | M23: =ROUND(VLOOKUP($B23,'CTC Breakup'!$B$2:$O$51,9,0)/31*$I23,0) -> 9000 | N23: =ROUND(VLOOKUP($B23,'CTC Breakup'!$B$2:$O$51,10,0)/31*$I23,0) -> 0 | O23: =ROUND(VLOOKUP($B23,'CTC Breakup'!$B$2:$O$51,11,0)/31*$I23,0) -> 0 | P23: =ROUND(((VLOOKUP($B23,'CTC Breakup'!$B$2:$N$51,13,0)-VLOOKUP($B23,'CTC Breakup'!$B$2:$N$51,12,0))/22/9)*$J23,0) -> 3027 | Q23: 9450 | R23: =SUM(K23:Q23) -> 47727 | S23: =ROUND(K23*12%,0) -> 2250 | T23: =ROUND(IF(R23>100000,R23*30%,IF(R23>75000,R23*20%,IF(R23>50000,R23*10%,0))),0) -> 0 | U23: 0 | V23: =R23-S23-T23-U23 -> 45477
A24: 46023 | B24: ASG0029 | C24: 45509 | E24: Payroll Analyst | F24: Payroll | G24: =VLOOKUP(tblPayroll[[#This Row],[Employee Id]],Table1[[Employee Id]:[Work Location]],13,0) -> Kolkata | H24: 0 | I24: =31-H24 -> 31 | J24: 0 | K24: =ROUND(VLOOKUP($B24,'CTC Breakup'!$B$2:$O$51,7,0)/31*$I24,0) -> 27084 | L24: =ROUND(VLOOKUP($B24,'CTC Breakup'!$B$2:$O$51,8,0)/31*$I24,0) -> 10834 | M24: =ROUND(VLOOKUP($B24,'CTC Breakup'!$B$2:$O$51,9,0)/31*$I24,0) -> 12999 | N24: =ROUND(VLOOKUP($B24,'CTC Breakup'!$B$2:$O$51,10,0)/31*$I24,0) -> 0 | O24: =ROUND(VLOOKUP($B24,'CTC Breakup'!$B$2:$O$51,11,0)/31*$I24,0) -> 0 | P24: =ROUND(((VLOOKUP($B24,'CTC Breakup'!$B$2:$N$51,13,0)-VLOOKUP($B24,'CTC Breakup'!$B$2:$N$51,12,0))/22/9)*$J24,0) -> 0 | Q24: 0 | R24: =SUM(K24:Q24) -> 50917 | S24: =ROUND(K24*12%,0) -> 3250 | T24: =ROUND(IF(R24>100000,R24*30%,IF(R24>75000,R24*20%,IF(R24>50000,R24*10%,0))),0) -> 5092 | U24: 0 | V24: =R24-S24-T24-U24 -> 42575
A25: 46023 | B25: ASG0030 | C25: 45537 | D25: 46098 | E25: Senior Data Analyst | F25: Analytics | G25: =VLOOKUP(tblPayroll[[#This Row],[Employee Id]],Table1[[Employee Id]:[Work Location]],13,0) -> Hyderabad | H25: 10 | I25: =31-H25 -> 21 | J25: 22 | K25: =ROUND(VLOOKUP($B25,'CTC Breakup'!$B$2:$O$51,7,0)/31*$I25,0) -> 40504 | L25: =ROUND(VLOOKUP($B25,'CTC Breakup'!$B$2:$O$51,8,0)/31*$I25,0) -> 16202 | M25: =ROUND(VLOOKUP($B25,'CTC Breakup'!$B$2:$O$51,9,0)/31*$I25,0) -> 17409 | N25: =ROUND(VLOOKUP($B25,'CTC Breakup'!$B$2:$O$51,10,0)/31*$I25,0) -> 1355 | O25: =ROUND(VLOOKUP($B25,'CTC Breakup'!$B$2:$O$51,11,0)/31*$I25,0) -> 677 | P25: =ROUND(((VLOOKUP($B25,'CTC Breakup'!$B$2:$N$51,13,0)-VLOOKUP($B25,'CTC Breakup'!$B$2:$N$51,12,0))/22/9)*$J25,0) -> 12490 | Q25: 0 | R25: =SUM(K25:Q25) -> 88637 | S25: =ROUND(K25*12%,0) -> 4860 | T25: =ROUND(IF(R25>100000,R25*30%,IF(R25>75000,R25*20%,IF(R25>50000,R25*5%,0))),0) -> 17727 | U25: 11100 | V25: =R25-S25-T25-U25 -> 54950
A26: 46023 | B26: ASG0031 | C26: 45579 | E26: Accounts Executive | F26: Finance | G26: =VLOOKUP(tblPayroll[[#This Row],[Employee Id]],Table1[[Employee Id]:[Work Location]],13,0) -> Bangalore | H26: 10 | I26: =31-H26 -> 21 | J26: 17 | K26: =ROUND(VLOOKUP($B26,'CTC Breakup'!$B$2:$O$51,7,0)/31*$I26,0) -> 19758 | L26: =ROUND(VLOOKUP($B26,'CTC Breakup'!$B$2:$O$51,8,0)/31*$I26,0) -> 7903 | M26: =ROUND(VLOOKUP($B26,'CTC Breakup'!$B$2:$O$51,9,0)/31*$I26,0) -> 9483 | N26: =ROUND(VLOOKUP($B26,'CTC Breakup'!$B$2:$O$51,10,0)/31*$I26,0) -> 0 | O26: =ROUND(VLOOKUP($B26,'CTC Breakup'!$B$2:$O$51,11,0)/31*$I26,0) -> 0 | P26: =ROUND(((VLOOKUP($B26,'CTC Breakup'!$B$2:$N$51,13,0)-VLOOKUP($B26,'CTC Breakup'!$B$2:$N$51,12,0))/22/9)*$J26,0) -> 4708 | Q26: 0 | R26: =SUM(K26:Q26) -> 41852 | S26: =ROUND(K26*12%,0) -> 2371 | T26: =ROUND(IF(R26>100000,R26*30%,IF(R26>75000,R26*20%,IF(R26>50000,R26*5%,0))),0) -> 0 | U26: 11400 | V26: =R26-S26-T26-U26 -> 28081
A27: 46023 | B27: ASG0032 | C27: 45607 | E27: HR Executive | F27: HR | G27: =VLOOKUP(tblPayroll[[#This Row],[Employee Id]],Table1[[Employee Id]:[Work Location]],13,0) -> Chennai | H27: 0 | I27: =31-H27 -> 31 | J27: 0 | K27: =ROUND(VLOOKUP($B27,'CTC Breakup'!$B$2:$O$51,7,0)/31*$I27,0) -> 31250 | L27: =ROUND(VLOOKUP($B27,'CTC Breakup'!$B$2:$O$51,8,0)/31*$I27,0) -> 12500 | M27: =ROUND(VLOOKUP($B27,'CTC Breakup'!$B$2:$O$51,9,0)/31*$I27,0) -> 15000 | N27: =ROUND(VLOOKUP($B27,'CTC Breakup'!$B$2:$O$51,10,0)/31*$I27,0) -> 0 | O27: =ROUND(VLOOKUP($B27,'CTC Breakup'!$B$2:$O$51,11,0)/31*$I27,0) -> 0 | P27: =ROUND(((VLOOKUP($B27,'CTC Breakup'!$B$2:$N$51,13,0)-VLOOKUP($B27,'CTC Breakup'!$B$2:$N$51,12,0))/22/9)*$J27,0) -> 0 | Q27: 0 | R27: =SUM(K27:Q27) -> 58750 | S27: =ROUND(K27*12%,0) -> 3750 | T27: =ROUND(IF(R27>100000,R27*30%,IF(R27>75000,R27*20%,IF(R27>50000,R27*10%,0))),0) -> 5875 | U27: 0 | V27: =R27-S27-T27-U27 -> 49125
A28: 46023 | B28: ASG0033 | C28: 45614 | E28: Data Analyst | F28: Analytics | G28: =VLOOKUP(tblPayroll[[#This Row],[Employee Id]],Table1[[Employee Id]:[Work Location]],13,0) -> Bangalore | H28: 0 | I28: =31-H28 -> 31 | J28: 0 | K28: =ROUND(VLOOKUP($B28,'CTC Breakup'!$B$2:$O$51,7,0)/31*$I28,0) -> 52084 | L28: =ROUND(VLOOKUP($B28,'CTC Breakup'!$B$2:$O$51,8,0)/31*$I28,0) -> 20834 | M28: =ROUND(VLOOKUP($B28,'CTC Breakup'!$B$2:$O$51,9,0)/31*$I28,0) -> 21999 | N28: =ROUND(VLOOKUP($B28,'CTC Breakup'!$B$2:$O$51,10,0)/31*$I28,0) -> 2000 | O28: =ROUND(VLOOKUP($B28,'CTC Breakup'!$B$2:$O$51,11,0)/31*$I28,0) -> 1000 | P28: =ROUND(((VLOOKUP($B28,'CTC Breakup'!$B$2:$N$51,13,0)-VLOOKUP($B28,'CTC Breakup'!$B$2:$N$51,12,0))/22/9)*$J28,0) -> 0 | Q28: 0 | R28: =SUM(K28:Q28) -> 97917 | S28: =ROUND(K28*12%,0) -> 6250 | T28: =ROUND(IF(R28>100000,R28*30%,IF(R28>75000,R28*20%,IF(R28>50000,R28*5%,0))),0) -> 19583 | U28: 0 | V28: =R28-S28-T28-U28 -> 72084
A29: 46023 | B29: ASG0034 | C29: 45649 | D29: 46041 | E29: HR Executive | F29: HR | G29: =VLOOKUP(tblPayroll[[#This Row],[Employee Id]],Table1[[Employee Id]:[Work Location]],13,0) -> Chennai | H29: 0 | I29: 19 | J29: 17 | K29: =ROUND(VLOOKUP($B29,'CTC Breakup'!$B$2:$O$51,7,0)/31*$I29,0) -> 15961 | L29: =ROUND(VLOOKUP($B29,'CTC Breakup'!$B$2:$O$51,8,0)/31*$I29,0) -> 6385 | M29: =ROUND(VLOOKUP($B29,'CTC Breakup'!$B$2:$O$51,9,0)/31*$I29,0) -> 7661 | N29: =ROUND(VLOOKUP($B29,'CTC Breakup'!$B$2:$O$51,10,0)/31*$I29,0) -> 0 | O29: =ROUND(VLOOKUP($B29,'CTC Breakup'!$B$2:$O$51,11,0)/31*$I29,0) -> 0 | P29: =ROUND(((VLOOKUP($B29,'CTC Breakup'!$B$2:$N$51,13,0)-VLOOKUP($B29,'CTC Breakup'!$B$2:$N$51,12,0))/22/9)*$J29,0) -> 4203 | Q29: 0 | R29: =SUM(K29:Q29) -> 34210 | S29: =ROUND(K29*12%,0) -> 1915 | T29: =ROUND(IF(R29>100000,R29*30%,IF(R29>75000,R29*20%,IF(R29>50000,R29*5%,0))),0) -> 0 | U29: 0 | V29: =R29-S29-T29-U29 -> 32295
A30: 46023 | B30: ASG0035 | C30: 45663 | E30: HR Executive | F30: HR | G30: =VLOOKUP(tblPayroll[[#This Row],[Employee Id]],Table1[[Employee Id]:[Work Location]],13,0) -> Mumbai | H30: 0 | I30: =31-H30 -> 31 | J30: 25 | K30: =ROUND(VLOOKUP($B30,'CTC Breakup'!$B$2:$O$51,7,0)/31*$I30,0) -> 25000 | L30: =ROUND(VLOOKUP($B30,'CTC Breakup'!$B$2:$O$51,8,0)/31*$I30,0) -> 10000 | M30: =ROUND(VLOOKUP($B30,'CTC Breakup'!$B$2:$O$51,9,0)/31*$I30,0) -> 12000 | N30: =ROUND(VLOOKUP($B30,'CTC Breakup'!$B$2:$O$51,10,0)/31*$I30,0) -> 0 | O30: =ROUND(VLOOKUP($B30,'CTC Breakup'!$B$2:$O$51,11,0)/31*$I30,0) -> 0 | P30: =ROUND(((VLOOKUP($B30,'CTC Breakup'!$B$2:$N$51,13,0)-VLOOKUP($B30,'CTC Breakup'!$B$2:$N$51,12,0))/22/9)*$J30,0) -> 5934 | Q30: 0 | R30: =SUM(K30:Q30) -> 52934 | S30: =ROUND(K30*12%,0) -> 3000 | T30: =ROUND(IF(R30>100000,R30*30%,IF(R30>75000,R30*20%,IF(R30>50000,R30*10%,0))),0) -> 5293 | U30: 0 | V30: =R30-S30-T30-U30 -> 44641
A31: 46023 | B31: ASG0036 | C31: 45782 | E31: Payroll Executive | F31: Payroll | G31: =VLOOKUP(tblPayroll[[#This Row],[Employee Id]],Table1[[Employee Id]:[Work Location]],13,0) -> Chennai | H31: 0 | I31: =31-H31 -> 31 | J31: 23 | K31: =ROUND(VLOOKUP($B31,'CTC Breakup'!$B$2:$O$51,7,0)/31*$I31,0) -> 19792 | L31: =ROUND(VLOOKUP($B31,'CTC Breakup'!$B$2:$O$51,8,0)/31*$I31,0) -> 7917 | M31: =ROUND(VLOOKUP($B31,'CTC Breakup'!$B$2:$O$51,9,0)/31*$I31,0) -> 9499 | N31: =ROUND(VLOOKUP($B31,'CTC Breakup'!$B$2:$O$51,10,0)/31*$I31,0) -> 0 | O31: =ROUND(VLOOKUP($B31,'CTC Breakup'!$B$2:$O$51,11,0)/31*$I31,0) -> 0 | P31: =ROUND(((VLOOKUP($B31,'CTC Breakup'!$B$2:$N$51,13,0)-VLOOKUP($B31,'CTC Breakup'!$B$2:$N$51,12,0))/22/9)*$J31,0) -> 4322 | Q31: 0 | R31: =SUM(K31:Q31) -> 41530 | S31: =ROUND(K31*12%,0) -> 2375 | T31: =ROUND(IF(R31>100000,R31*30%,IF(R31>75000,R31*20%,IF(R31>50000,R31*5%,0))),0) -> 0 | U31: 0 | V31: =R31-S31-T31-U31 -> 39155
A32: 46023 | B32: ASG0038 | C32: 45852 | E32: Accounts Trainee | F32: Finance | G32: =VLOOKUP(tblPayroll[[#This Row],[Employee Id]],Table1[[Employee Id]:[Work Location]],13,0) -> Mumbai | H32: 0 | I32: =31-H32 -> 31 | J32: 25 | K32: =ROUND(VLOOKUP($B32,'CTC Breakup'!$B$2:$O$51,7,0)/31*$I32,0) -> 18750 | L32: =ROUND(VLOOKUP($B32,'CTC Breakup'!$B$2:$O$51,8,0)/31*$I32,0) -> 7500 | M32: =ROUND(VLOOKUP($B32,'CTC Breakup'!$B$2:$O$51,9,0)/31*$I32,0) -> 9000 | N32: =ROUND(VLOOKUP($B32,'CTC Breakup'!$B$2:$O$51,10,0)/31*$I32,0) -> 0 | O32: =ROUND(VLOOKUP($B32,'CTC Breakup'!$B$2:$O$51,11,0)/31*$I32,0) -> 0 | P32: =ROUND(((VLOOKUP($B32,'CTC Breakup'!$B$2:$N$51,13,0)-VLOOKUP($B32,'CTC Breakup'!$B$2:$N$51,12,0))/22/9)*$J32,0) -> 4451 | Q32: 0 | R32: =SUM(K32:Q32) -> 39701 | S32: =ROUND(K32*12%,0) -> 2250 | T32: =ROUND(IF(R32>100000,R32*30%,IF(R32>75000,R32*20%,IF(R32>50000,R32*5%,0))),0) -> 0 | U32: 0 | V32: =R32-S32-T32-U32 -> 37451
